2023-11-02 16:10:40,761 [21] ERROR KaazingTestWebApplication.WebApiExceptionFilter [(null)] - TaskCanceledException:An unhandled exception was thrown by Custom Web API exception handler(工作已取消。)
System.Threading.Tasks.TaskCanceledException: 工作已取消。
   於 System.Runtime.CompilerServices.TaskAwaiter.ThrowForNonSuccess(Task task)
   於 System.Runtime.CompilerServices.TaskAwaiter.HandleNonSuccessAndDebuggerNotification(Task task)
   於 System.Web.Http.Controllers.ApiControllerActionInvoker.<InvokeActionAsyncCore>d__0.MoveNext()
--- 先前擲回例外狀況之位置中的堆疊追蹤結尾 ---
   於 System.Runtime.ExceptionServices.ExceptionDispatchInfo.Throw()
   於 System.Runtime.CompilerServices.TaskAwaiter.ThrowForNonSuccess(Task task)
   於 System.Runtime.CompilerServices.TaskAwaiter.HandleNonSuccessAndDebuggerNotification(Task task)
   於 System.Web.Http.Controllers.ActionFilterResult.<ExecuteAsync>d__2.MoveNext()
--- 先前擲回例外狀況之位置中的堆疊追蹤結尾 ---
   於 System.Runtime.ExceptionServices.ExceptionDispatchInfo.Throw()
   於 System.Runtime.CompilerServices.TaskAwaiter.ThrowForNonSuccess(Task task)
   於 System.Runtime.CompilerServices.TaskAwaiter.HandleNonSuccessAndDebuggerNotification(Task task)
   於 System.Web.Http.Controllers.ExceptionFilterResult.<ExecuteAsync>d__0.MoveNext()
2023-11-02 16:31:17,932 [10] ERROR KaazingTestWebApplication.WebApiExceptionFilter [(null)] - TaskCanceledException:An unhandled exception was thrown by Custom Web API exception handler(工作已取消。)
System.Threading.Tasks.TaskCanceledException: 工作已取消。
   於 System.Runtime.CompilerServices.TaskAwaiter.ThrowForNonSuccess(Task task)
   於 System.Runtime.CompilerServices.TaskAwaiter.HandleNonSuccessAndDebuggerNotification(Task task)
   於 System.Web.Http.Controllers.ApiControllerActionInvoker.<InvokeActionAsyncCore>d__0.MoveNext()
--- 先前擲回例外狀況之位置中的堆疊追蹤結尾 ---
   於 System.Runtime.ExceptionServices.ExceptionDispatchInfo.Throw()
   於 System.Runtime.CompilerServices.TaskAwaiter.ThrowForNonSuccess(Task task)
   於 System.Runtime.CompilerServices.TaskAwaiter.HandleNonSuccessAndDebuggerNotification(Task task)
   於 System.Web.Http.Controllers.ActionFilterResult.<ExecuteAsync>d__2.MoveNext()
--- 先前擲回例外狀況之位置中的堆疊追蹤結尾 ---
   於 System.Runtime.ExceptionServices.ExceptionDispatchInfo.Throw()
   於 System.Runtime.CompilerServices.TaskAwaiter.ThrowForNonSuccess(Task task)
   於 System.Runtime.CompilerServices.TaskAwaiter.HandleNonSuccessAndDebuggerNotification(Task task)
   於 System.Web.Http.Controllers.ExceptionFilterResult.<ExecuteAsync>d__0.MoveNext()
